Workbook

Sheet Start_Here
A1: Inventory & Procurement Planning Simulation
A2: Portfolio-ready Excel model | Synthetic retail data | No coding required
A4: Project purpose | B4: Analyze stock levels, supplier trade-offs, replenishment needs and estimated procurement costs for a fictional retail business.
A5: Data note | B5: All product, supplier and cost data are synthetic and for educational demonstration only.
A6: Recommended workflow | B6: 1. Review Inventory_Master. 2. Compare Supplier_Comparison. 3. Review Cost_Assumptions. 4. Analyze Replenishment_Plan and Scenario_Analysis. 5. Review Cost_Analysis and Management_Dashboard.
A7: Inventory_Master | B7: 30 SKUs across five categories. Reorder point and inventory value are formula-driven.
A8: Supplier_Comparison | B8: Three supplier quotes per SKU. Supplier scores are normalized within each SKU and weighted.
A9: Cost_Assumptions | B9: Yellow cells are editable assumptions. Change values to test alternative operating conditions.
A10: Replenishment_Plan | B10: Shows reorder status, recommended supplier, MOQ-adjusted order quantity and estimated purchase cost.
A11: Scenario_Analysis | B11: Compares baseline, 30% higher demand, and four additional days of supplier delay.
A12: Cost_Analysis | B12: Estimates annual holding cost, ordering cost and purchase cost. Stockout penalty is an illustrative risk proxy, not a forecast.
A13: Management_Dashboard | B13: Summary KPIs and charts. Excel may need to recalculate formulas when first opened.
A14: Supplier scoring | B14: Price 40%, lead time 25%, defect-rate quality score 20%, on-time delivery 15%. Higher weighted score is preferred.
A15: Model limitations | B15: Demand is assumed stable within each scenario; actual seasonality, supplier capacity, taxes, freight, cash constraints and uncertain lead times are not modeled.
A16: Portfolio deliverables | B16: Workbook, README, analysis report, screenshots. Include findings only after reviewing the calculated workbook results.

Sheet Inventory_Master
A1: Inventory Master
A2: 30 fictional products. Verify formulas before using the workbook for portfolio conclusions.
A3: SKU | B3: Product | C3: Category | D3: Unit Cost (₹) | E3: Current Stock (units) | F3: Avg Daily Demand (units) | G3: Lead Time (days) | H3: Safety Stock (units) | I3: Reorder Point (units) | J3: Inventory Value (₹) | K3: Recommended Supplier | L3: Supplier Unit Price (₹) | M3: Supplier Lead Time (days) | N3: Supplier MOQ (units) | O3: Supplier Score
A4: SKU001 | B4: Wireless Mouse | C4: Electronics | D4: 650 | E4: 74 | F4: 6 | G4: 3 | H4: 24 | I4: =F4*G4+H4 | J4: =D4*E4 | K4: Supplier A | L4: 635.21 | M4: 3 | N4: 10 | O4: 82.256429
A5: SKU002 | B5: USB-C Cable | C5: Electronics | D5: 180 | E5: 165 | F5: 7 | G5: 4 | H5: 14 | I5: =F5*G5+H5 | J5: =D5*E5 | K5: Supplier C | L5: 199.18 | M5: 6 | N5: 25 | O5: 88.700101
A6: SKU003 | B6: Laptop Stand | C6: Electronics | D6: 300 | E6: 35 | F6: 4 | G6: 3 | H6: 8 | I6: =F6*G6+H6 | J6: =D6*E6 | K6: Supplier C | L6: 327.71 | M6: 3 | N6: 20 | O6: 93.897872
A7: SKU004 | B7: Bluetooth Speaker | C7: Electronics | D7: 180 | E7: 89 | F7: 3 | G7: 11 | H7: 9 | I7: =F7*G7+H7 | J7: =D7*E7 | K7: Supplier C | L7: 180.38 | M7: 4 | N7: 10 | O7: 86.301287
A8: SKU005 | B8: Power Bank | C8: Electronics | D8: 800 | E8: 333 | F8: 16 | G8: 6 | H8: 80 | I8: =F8*G8+H8 | J8: =D8*E8 | K8: Supplier A | L8: 802.66 | M8: 3 | N8: 10 | O8: 96.129774
A9: SKU006 | B9: Desk Lamp | C9: Home | D9: 220 | E9: 49 | F9: 3 | G9: 5 | H9: 15 | I9: =F9*G9+H9 | J9: =D9*E9 | K9: Supplier A | L9: 198.58 | M9: 11 | N9: 10 | O9: 84.015909
A10: SKU007 | B10: Storage Box | C10: Home | D10: 220 | E10: 40 | F10: 7 | G10: 6 | H10: 28 | I10: =F10*G10+H10 | J10: =D10*E10 | K10: Supplier B | L10: 259.3 | M10: 11 | N10: 50 | O10: 90.067612
A11: SKU008 | B11: Water Bottle | C11: Lifestyle | D11: 120 | E11: 206 | F11: 15 | G11: 4 | H11: 60 | I11: =F11*G11+H11 | J11: =D11*E11 | K11: Supplier A | L11: 126.63 | M11: 11 | N11: 20 | O11: 77.747539
A12: SKU009 | B12: Travel Mug | C12: Lifestyle | D12: 500 | E12: 85 | F12: 11 | G12: 3 | H12: 55 | I12: =F12*G12+H12 | J12: =D12*E12 | K12: Supplier C | L12: 485 | M12: 8 | N12: 10 | O12: 90.213093
A13: SKU010 | B13: Notebook Set | C13: Stationery | D13: 1500 | E13: 351 | F13: 15 | G13: 4 | H13: 60 | I13: =F13*G13+H13 | J13: =D13*E13 | K13: Supplier A | L13: 1573.35 | M13: 4 | N13: 10 | O13: 93.994459
A14: SKU011 | B14: Ballpoint Pens | C14: Stationery | D14: 500 | E14: 388 | F14: 14 | G14: 12 | H14: 42 | I14: =F14*G14+H14 | J14: =D14*E14 | K14: Supplier A | L14: 538.1 | M14: 3 | N14: 25 | O14: 88.275647
A15: SKU012 | B15: Backpack | C15: Lifestyle | D15: 120 | E15: 18 | F15: 4 | G15: 6 | H15: 16 | I15: =F15*G15+H15 | J15: =D15*E15 | K15: Supplier C | L15: 117.61 | M15: 5 | N15: 25 | O15: 95.337709
... A33: SKU030 | B33: Pen Holder | C33: Stationery | D33: 250 | E33: 169 | F33: 8 | G33: 11 | H33: 16 | I33: =F33*G33+H33 | J33: =D33*E33 | K33: Supplier B | L33: 225.7 | M33: 13 | N33: 20 | O33: 87.253395

Sheet Supplier_Comparison
A1: Supplier Comparison
A2: Compare price, lead time, MOQ, quality and reliability. Scores are relative within each SKU.
A3: SKU | B3: Product | C3: Supplier | D3: Unit Price (₹) | E3: Lead Time (days) | F3: MOQ (units) | G3: Defect Rate (%) | H3: On-time Delivery (%) | I3: Price Score (0-100) | J3: Lead Score (0-100) | K3: Quality Score (0-100) | L3: Reliability Score (0-100) | M3: Weighted Score | N3: Rank per SKU
A4: SKU001 | B4: Wireless Mouse | C4: Supplier A | D4: 635.21 | E4: 3 | F4: 10 | G4: 4.2 | H4: 97.9 | I4: =MIN($D$4:$D$6)/D4*100 | J4: =MIN($E$4:$E$6)/E4*100 | K4: =MIN($G$4:$G$6)/G4*100 | L4: =H4 | M4: =I4*40%+J4*25%+K4*20%+L4*15% | N4: =RANK(M4,$M$4:$M$6,0)
A5: SKU001 | B5: Wireless Mouse | C5: Supplier B | D5: 734.17 | E5: 7 | F5: 20 | G5: 0.54 | H5: 97.9 | I5: =MIN($D$4:$D$6)/D5*100 | J5: =MIN($E$4:$E$6)/E5*100 | K5: =MIN($G$4:$G$6)/G5*100 | L5: =H5 | M5: =I5*40%+J5*25%+K5*20%+L5*15% | N5: =RANK(M5,$M$4:$M$6,0)
A6: SKU001 | B6: Wireless Mouse | C6: Supplier C | D6: 756.66 | E6: 4 | F6: 50 | G6: 3.73 | H6: 99.2 | I6: =MIN($D$4:$D$6)/D6*100 | J6: =MIN($E$4:$E$6)/E6*100 | K6: =MIN($G$4:$G$6)/G6*100 | L6: =H6 | M6: =I6*40%+J6*25%+K6*20%+L6*15% | N6: =RANK(M6,$M$4:$M$6,0)
A7: SKU002 | B7: USB-C Cable | C7: Supplier A | D7: 187.17 | E7: 5 | F7: 20 | G7: 3.07 | H7: 98.8 | I7: =MIN($D$7:$D$9)/D7*100 | J7: =MIN($E$7:$E$9)/E7*100 | K7: =MIN($G$7:$G$9)/G7*100 | L7: =H7 | M7: =I7*40%+J7*25%+K7*20%+L7*15% | N7: =RANK(M7,$M$7:$M$9,0)
A8: SKU002 | B8: USB-C Cable | C8: Supplier B | D8: 167.32 | E8: 11 | F8: 50 | G8: 4.35 | H8: 98.5 | I8: =MIN($D$7:$D$9)/D8*100 | J8: =MIN($E$7:$E$9)/E8*100 | K8: =MIN($G$7:$G$9)/G8*100 | L8: =H8 | M8: =I8*40%+J8*25%+K8*20%+L8*15% | N8: =RANK(M8,$M$7:$M$9,0)
A9: SKU002 | B9: USB-C Cable | C9: Supplier C | D9: 199.18 | E9: 6 | F9: 25 | G9: 1.98 | H9: 95.1 | I9: =MIN($D$7:$D$9)/D9*100 | J9: =MIN($E$7:$E$9)/E9*100 | K9: =MIN($G$7:$G$9)/G9*100 | L9: =H9 | M9: =I9*40%+J9*25%+K9*20%+L9*15% | N9: =RANK(M9,$M$7:$M$9,0)
A10: SKU003 | B10: Laptop Stand | C10: Supplier A | D10: 297.61 | E10: 11 | F10: 50 | G10: 0.81 | H10: 89 | I10: =MIN($D$10:$D$12)/D10*100 | J10: =MIN($E$10:$E$12)/E10*100 | K10: =MIN($G$10:$G$12)/G10*100 | L10: =H10 | M10: =I10*40%+J10*25%+K10*20%+L10*15% | N10: =RANK(M10,$M$10:$M$12,0)
A11: SKU003 | B11: Laptop Stand | C11: Supplier B | D11: 294.43 | E11: 12 | F11: 20 | G11: 2.77 | H11: 86.1 | I11: =MIN($D$10:$D$12)/D11*100 | J11: =MIN($E$10:$E$12)/E11*100 | K11: =MIN($G$10:$G$12)/G11*100 | L11: =H11 | M11: =I11*40%+J11*25%+K11*20%+L11*15% | N11: =RANK(M11,$M$10:$M$12,0)
A12: SKU003 | B12: Laptop Stand | C12: Supplier C | D12: 327.71 | E12: 3 | F12: 20 | G12: 0.58 | H12: 86.4 | I12: =MIN($D$10:$D$12)/D12*100 | J12: =MIN($E$10:$E$12)/E12*100 | K12: =MIN($G$10:$G$12)/G12*100 | L12: =H12 | M12: =I12*40%+J12*25%+K12*20%+L12*15% | N12: =RANK(M12,$M$10:$M$12,0)
A13: SKU004 | B13: Bluetooth Speaker | C13: Supplier A | D13: 176.24 | E13: 11 | F13: 20 | G13: 1.47 | H13: 92.6 | I13: =MIN($D$13:$D$15)/D13*100 | J13: =MIN($E$13:$E$15)/E13*100 | K13: =MIN($G$13:$G$15)/G13*100 | L13: =H13 | M13: =I13*40%+J13*25%+K13*20%+L13*15% | N13: =RANK(M13,$M$13:$M$15,0)
A14: SKU004 | B14: Bluetooth Speaker | C14: Supplier B | D14: 187.52 | E14: 12 | F14: 50 | G14: 1.32 | H14: 92.4 | I14: =MIN($D$13:$D$15)/D14*100 | J14: =MIN($E$13:$E$15)/E14*100 | K14: =MIN($G$13:$G$15)/G14*100 | L14: =H14 | M14: =I14*40%+J14*25%+K14*20%+L14*15% | N14: =RANK(M14,$M$13:$M$15,0)
A15: SKU004 | B15: Bluetooth Speaker | C15: Supplier C | D15: 180.38 | E15: 4 | F15: 10 | G15: 3.07 | H15: 90.8 | I15: =MIN($D$13:$D$15)/D15*100 | J15: =MIN($E$13:$E$15)/E15*100 | K15: =MIN($G$13:$G$15)/G15*100 | L15: =H15 | M15: =I15*40%+J15*25%+K15*20%+L15*15% | N15: =RANK(M15,$M$13:$M$15,0)
A16: SKU005 | B16: Power Bank | C16: Supplier A | D16: 802.66 | E16: 3 | F16: 10 | G16: 0.55 | H16: 95.8 | I16: =MIN($D$16:$D$18)/D16*100 | J16: =MIN($E$16:$E$18)/E16*100 | K16: =MIN($G$16:$G$18)/G16*100 | L16: =H16 | M16: =I16*40%+J16*25%+K16*20%+L16*15% | N16: =RANK(M16,$M$16:$M$18,0)
A17: SKU005 | B17: Power Bank | C17: Supplier B | D17: 896.14 | E17: 4 | F17: 20 | G17: 1.1 | H17: 93.2 | I17: =MIN($D$16:$D$18)/D17*100 | J17: =MIN($E$16:$E$18)/E17*100 | K17: =MIN($G$16:$G$18)/G17*100 | L17: =H17 | M17: =I17*40%+J17*25%+K17*20%+L17*15% | N17: =RANK(M17,$M$16:$M$18,0)
A18: SKU005 | B18: Power Bank | C18: Supplier C | D18: 737.64 | E18: 5 | F18: 25 | G18: 2.24 | H18: 97.8 | I18: =MIN($D$16:$D$18)/D18*100 | J18: =MIN($E$16:$E$18)/E18*100 | K18: =MIN($G$16:$G$18)/G18*100 | L18: =H18 | M18: =I18*40%+J18*25%+K18*20%+L18*15% | N18: =RANK(M18,$M$16:$M$18,0)
A19: SKU006 | B19: Desk Lamp | C19: Supplier A | D19: 198.58 | E19: 11 | F19: 10 | G19: 0.51 | H19: 99.5 | I19: =MIN($D$19:$D$21)/D19*100 | J19: =MIN($E$19:$E$21)/E19*100 | K19: =MIN($G$19:$G$21)/G19*100 | L19: =H19 | M19: =I19*40%+J19*25%+K19*20%+L19*15% | N19: =RANK(M19,$M$19:$M$21,0)
A20: SKU006 | B20: Desk Lamp | C20: Supplier B | D20: 248.78 | E20: 4 | F20: 20 | G20: 1 | H20: 92.6 | I20: =MIN($D$19:$D$21)/D20*100 | J20: =MIN($E$19:$E$21)/E20*100 | K20: =MIN($G$19:$G$21)/G20*100 | L20: =H20 | M20: =I20*40%+J20*25%+K20*20%+L20*15% | N20: =RANK(M20,$M$19:$M$21,0)
A21: SKU006 | B21: Desk Lamp | C21: Supplier C | D21: 207.71 | E21: 9 | F21: 10 | G21: 0.99 | H21: 86 | I21: =MIN($D$19:$D$21)/D21*100 | J21: =MIN($E$19:$E$21)/E21*100 | K21: =MIN($G$19:$G$21)/G21*100 | L21: =H21 | M21: =I21*40%+J21*25%+K21*20%+L21*15% | N21: =RANK(M21,$M$19:$M$21,0)
A22: SKU007 | B22: Storage Box | C22: Supplier A | D22: 219.37 | E22: 10 | F22: 25 | G22: 2.08 | H22: 98.9 | I22: =MIN($D$22:$D$24)/D22*100 | J22: =MIN($E$22:$E$24)/E22*100 | K22: =MIN($G$22:$G$24)/G22*100 | L22: =H22 | M22: =I22*40%+J22*25%+K22*20%+L22*15% | N22: =RANK(M22,$M$22:$M$24,0)
A23: SKU007 | B23: Storage Box | C23: Supplier B | D23: 259.3 | E23: 11 | F23: 50 | G23: 0.95 | H23: 90 | I23: =MIN($D$22:$D$24)/D23*100 | J23: =MIN($E$22:$E$24)/E23*100 | K23: =MIN($G$22:$G$24)/G23*100 | L23: =H23 | M23: =I23*40%+J23*25%+K23*20%+L23*15% | N23: =RANK(M23,$M$22:$M$24,0)
A24: SKU007 | B24: Storage Box | C24: Supplier C | D24: 257.53 | E24: 12 | F24: 10 | G24: 3.44 | H24: 86.8 | I24: =MIN($D$22:$D$24)/D24*100 | J24: =MIN($E$22:$E$24)/E24*100 | K24: =MIN($G$22:$G$24)/G24*100 | L24: =H24 | M24: =I24*40%+J24*25%+K24*20%+L24*15% | N24: =RANK(M24,$M$22:$M$24,0)
A25: SKU008 | B25: Water Bottle | C25: Supplier A | D25: 126.63 | E25: 11 | F25: 20 | G25: 0.54 | H25: 92.9 | I25: =MIN($D$25:$D$27)/D25*100 | J25: =MIN($E$25:$E$27)/E25*100 | K25: =MIN($G$25:$G$27)/G25*100 | L25: =H25 | M25: =I25*40%+J25*25%+K25*20%+L25*15% | N25: =RANK(M25,$M$25:$M$27,0)
A26: SKU008 | B26: Water Bottle | C26: Supplier B | D26: 136.25 | E26: 4 | F26: 10 | G26: 3.14 | H26: 89.2 | I26: =MIN($D$25:$D$27)/D26*100 | J26: =MIN($E$25:$E$27)/E26*100 | K26: =MIN($G$25:$G$27)/G26*100 | L26: =H26 | M26: =I26*40%+J26*25%+K26*20%+L26*15% | N26: =RANK(M26,$M$25:$M$27,0)
A27: SKU008 | B27: Water Bottle | C27: Supplier C | D27: 109.92 | E27: 12 | F27: 20 | G27: 2.73 | H27: 86.5 | I27: =MIN($D$25:$D$27)/D27*100 | J27: =MIN($E$25:$E$27)/E27*100 | K27: =MIN($G$25:$G$27)/G27*100 | L27: =H27 | M27: =I27*40%+J27*25%+K27*20%+L27*15% | N27: =RANK(M27,$M$25:$M$27,0)
A28: SKU009 | B28: Travel Mug | C28: Supplier A | D28: 452.3 | E28: 13 | F28: 25 | G28: 4.23 | H28: 88.8 | I28: =MIN($D$28:$D$30)/D28*100 | J28: =MIN($E$28:$E$30)/E28*100 | K28: =MIN($G$28:$G$30)/G28*100 | L28: =H28 | M28: =I28*40%+J28*25%+K28*20%+L28*15% | N28: =RANK(M28,$M$28:$M$30,0)
A29: SKU009 | B29: Travel Mug | C29: Supplier B | D29: 547.43 | E29: 6 | F29: 25 | G29: 1.96 | H29: 95.1 | I29: =MIN($D$28:$D$30)/D29*100 | J29: =MIN($E$28:$E$30)/E29*100 | K29: =MIN($G$28:$G$30)/G29*100 | L29: =H29 | M29: =I29*40%+J29*25%+K29*20%+L29*15% | N29: =RANK(M29,$M$28:$M$30,0)
A30: SKU009 | B30: Travel Mug | C30: Supplier C | D30: 485 | E30: 8 | F30: 10 | G30: 0.34 | H30: 94.4 | I30: =MIN($D$28:$D$30)/D30*100 | J30: =MIN($E$28:$E$30)/E30*100 | K30: =MIN($G$28:$G$30)/G30*100 | L30: =H30 | M30: =I30*40%+J30*25%+K30*20%+L30*15% | N30: =RANK(M30,$M$28:$M$30,0)
A31: SKU010 | B31: Notebook Set | C31: Supplier A | D31: 1573.35 | E31: 4 | F31: 10 | G31: 2.56 | H31: 92.8 | I31: =MIN($D$31:$D$33)/D31*100 | J31: =MIN($E$31:$E$33)/E31*100 | K31: =MIN($G$31:$G$33)/G31*100 | L31: =H31 | M31: =I31*40%+J31*25%+K31*20%+L31*15% | N31: =RANK(M31,$M$31:$M$33,0)
A32: SKU010 | B32: Notebook Set | C32: Supplier B | D32: 1379.61 | E32: 8 | F32: 10 | G32: 3.99 | H32: 91 | I32: =MIN($D$31:$D$33)/D32*100 | J32: =MIN($E$31:$E$33)/E32*100 | K32: =MIN($G$31:$G$33)/G32*100 | L32: =H32 | M32: =I32*40%+J32*25%+K32*20%+L32*15% | N32: =RANK(M32,$M$31:$M$33,0)
A33: SKU010 | B33: Notebook Set | C33: Supplier C | D33: 1390.99 | E33: 11 | F33: 25 | G33: 2.87 | H33: 99.3 | I33: =MIN($D$31:$D$33)/D33*100 | J33: =MIN($E$31:$E$33)/E33*100 | K33: =MIN($G$31:$G$33)/G33*100 | L33: =H33 | M33: =I33*40%+J33*25%+K33*20%+L33*15% | N33: =RANK(M33,$M$31:$M$33,0)
A34: SKU011 | B34: Ballpoint Pens | C34: Supplier A | D34: 538.1 | E34: 3 | F34: 25 | G34: 4.21 | H34: 87.4 | I34: =MIN($D$34:$D$36)/D34*100 | J34: =MIN($E$34:$E$36)/E34*100 | K34: =MIN($G$34:$G$36)/G34*100 | L34: =H34 | M34: =I34*40%+J34*25%+K34*20%+L34*15% | N34: =RANK(M34,$M$34:$M$36,0)
A35: SKU011 | B35: Ballpoint Pens | C35: Supplier B | D35: 571.72 | E35: 7 | F35: 10 | G35: 4.04 | H35: 96 | I35: =MIN($D$34:$D$36)/D35*100 | J35: =MIN($E$34:$E$36)/E35*100 | K35: =MIN($G$34:$G$36)/G35*100 | L35: =H35 | M35: =I35*40%+J35*25%+K35*20%+L35*15% | N35: =RANK(M35,$M$34:$M$36,0)
A36: SKU011 | B36: Ballpoint Pens | C36: Supplier C | D36: 463.32 | E36: 7 | F36: 20 | G36: 3.31 | H36: 88.7 | I36: =MIN($D$34:$D$36)/D36*100 | J36: =MIN($E$34:$E$36)/E36*100 | K36: =MIN($G$34:$G$36)/G36*100 | L36: =H36 | M36: =I36*40%+J36*25%+K36*20%+L36*15% | N36: =RANK(M36,$M$34:$M$36,0)
A37: SKU012 | B37: Backpack | C37: Supplier A | D37: 128.43 | E37: 7 | F37: 50 | G37: 1.35 | H37: 98.3 | I37: =MIN($D$37:$D$39)/D37*100 | J37: =MIN($E$37:$E$39)/E37*100 | K37: =MIN($G$37:$G$39)/G37*100 | L37: =H37 | M37: =I37*40%+J37*25%+K37*20%+L37*15% | N37: =RANK(M37,$M$37:$M$39,0)
A38: SKU012 | B38: Backpack | C38: Supplier B | D38: 107.43 | E38: 13 | F38: 50 | G38: 3.78 | H38: 86.6 | I38: =MIN($D$37:$D$39)/D38*100 | J38: =MIN($E$37:$E$39)/E38*100 | K38: =MIN($G$37:$G$39)/G38*100 | L38: =H38 | M38: =I38*40%+J38*25%+K38*20%+L38*15% | N38: =RANK(M38,$M$37:$M$39,0)
A39: SKU012 | B39: Backpack | C39: Supplier C | D39: 117.61 | E39: 5 | F39: 25 | G39: 0.98 | H39: 92 | I39: =MIN($D$37:$D$39)/D39*100 | J39: =MIN($E$37:$E$39)/E39*100 | K39: =MIN($G$37:$G$39)/G39*100 | L39: =H39 | M39: =I39*40%+J39*25%+K39*20%+L39*15% | N39: =RANK(M39,$M$37:$M$39,0)
A40: SKU013 | B40: Phone Case | C40: Supplier A | D40: 1310.04 | E40: 11 | F40: 10 | G40: 0.77 | H40: 98.8 | I40: =MIN($D$40:$D$42)/D40*100 | J40: =MIN($E$40:$E$42)/E40*100 | K40: =MIN($G$40:$G$42)/G40*100 | L40: =H40 | M40: =I40*40%+J40*25%+K40*20%+L40*15% | N40: =RANK(M40,$M$40:$M$42,0)
...

Sheet Cost_Assumptions
A1: Cost & Scenario Assumptions
A2: Edit yellow cells to test different business conditions; values are illustrative, not industry benchmarks.
A3: Assumption | B3: Value | C3: Unit / explanation
A4: Annual holding cost rate | B4: 0.22 | C4: 22% of average inventory value per year
A5: Ordering cost per purchase order | B5: 450 | C5: ₹ per order
A6: Stockout penalty per unit | B6: 180 | C6: ₹ per unmet unit; used only as a risk proxy
A7: High-demand multiplier | B7: 1.3 | C7: 1.30 means demand increases by 30%
A8: Extra supplier delay | B8: 4 | C8: Additional days
A9: Extra target stock cover | B9: 14 | C9: Days of demand beyond lead-time and safety stock
A10: Planning horizon | B10: 30 | C10: Days used for illustrative scenario exposure

Sheet Replenishment_Plan
A1: Replenishment Plan
A2: Recommended quantities are model outputs. Check supplier MOQ and operational context before making a real order.
A3: SKU | B3: Product | C3: Current Stock | D3: Daily Demand | E3: Lead Time | F3: Safety Stock | G3: Reorder Point | H3: Status | I3: Target Stock | J3: Base Order Qty | K3: Supplier MOQ | L3: MOQ-Adjusted Order Qty | M3: Recommended Supplier | N3: Unit Price (₹) | O3: Purchase Cost (₹) | P3: Order Count | Q3: Annual Holding Cost (₹)
A4: =Inventory_Master!A4 | B4: =Inventory_Master!B4 | C4: =Inventory_Master!E4 | D4: =Inventory_Master!F4 | E4: =Inventory_Master!G4 | F4: =Inventory_Master!H4 | G4: =Inventory_Master!I4 | H4: =IF(C4<=G4,"REORDER","OK") | I4: =D4*E4+F4+D4*Cost_Assumptions!$B$9 | J4: =MAX(0,I4-C4) | K4: =Inventory_Master!N4 | L4: =IF(J4=0,0,MAX(J4,K4)) | M4: =Inventory_Master!K4 | N4: =Inventory_Master!L4 | O4: =L4*N4 | P4: =IF(L4>0,1,0) | Q4: =C4*Inventory_Master!D4*Cost_Assumptions!$B$4
A5: =Inventory_Master!A5 | B5: =Inventory_Master!B5 | C5: =Inventory_Master!E5 | D5: =Inventory_Master!F5 | E5: =Inventory_Master!G5 | F5: =Inventory_Master!H5 | G5: =Inventory_Master!I5 | H5: =IF(C5<=G5,"REORDER","OK") | I5: =D5*E5+F5+D5*Cost_Assumptions!$B$9 | J5: =MAX(0,I5-C5) | K5: =Inventory_Master!N5 | L5: =IF(J5=0,0,MAX(J5,K5)) | M5: =Inventory_Master!K5 | N5: =Inventory_Master!L5 | O5: =L5*N5 | P5: =IF(L5>0,1,0) | Q5: =C5*Inventory_Master!D5*Cost_Assumptions!$B$4
A6: =Inventory_Master!A6 | B6: =Inventory_Master!B6 | C6: =Inventory_Master!E6 | D6: =Inventory_Master!F6 | E6: =Inventory_Master!G6 | F6: =Inventory_Master!H6 | G6: =Inventory_Master!I6 | H6: =IF(C6<=G6,"REORDER","OK") | I6: =D6*E6+F6+D6*Cost_Assumptions!$B$9 | J6: =MAX(0,I6-C6) | K6: =Inventory_Master!N6 | L6: =IF(J6=0,0,MAX(J6,K6)) | M6: =Inventory_Master!K6 | N6: =Inventory_Master!L6 | O6: =L6*N6 | P6: =IF(L6>0,1,0) | Q6: =C6*Inventory_Master!D6*Cost_Assumptions!$B$4
A7: =Inventory_Master!A7 | B7: =Inventory_Master!B7 | C7: =Inventory_Master!E7 | D7: =Inventory_Master!F7 | E7: =Inventory_Master!G7 | F7: =Inventory_Master!H7 | G7: =Inventory_Master!I7 | H7: =IF(C7<=G7,"REORDER","OK") | I7: =D7*E7+F7+D7*Cost_Assumptions!$B$9 | J7: =MAX(0,I7-C7) | K7: =Inventory_Master!N7 | L7: =IF(J7=0,0,MAX(J7,K7)) | M7: =Inventory_Master!K7 | N7: =Inventory_Master!L7 | O7: =L7*N7 | P7: =IF(L7>0,1,0) | Q7: =C7*Inventory_Master!D7*Cost_Assumptions!$B$4
A8: =Inventory_Master!A8 | B8: =Inventory_Master!B8 | C8: =Inventory_Master!E8 | D8: =Inventory_Master!F8 | E8: =Inventory_Master!G8 | F8: =Inventory_Master!H8 | G8: =Inventory_Master!I8 | H8: =IF(C8<=G8,"REORDER","OK") | I8: =D8*E8+F8+D8*Cost_Assumptions!$B$9 | J8: =MAX(0,I8-C8) | K8: =Inventory_Master!N8 | L8: =IF(J8=0,0,MAX(J8,K8)) | M8: =Inventory_Master!K8 | N8: =Inventory_Master!L8 | O8: =L8*N8 | P8: =IF(L8>0,1,0) | Q8: =C8*Inventory_Master!D8*Cost_Assumptions!$B$4
A9: =Inventory_Master!A9 | B9: =Inventory_Master!B9 | C9: =Inventory_Master!E9 | D9: =Inventory_Master!F9 | E9: =Inventory_Master!G9 | F9: =Inventory_Master!H9 | G9: =Inventory_Master!I9 | H9: =IF(C9<=G9,"REORDER","OK") | I9: =D9*E9+F9+D9*Cost_Assumptions!$B$9 | J9: =MAX(0,I9-C9) | K9: =Inventory_Master!N9 | L9: =IF(J9=0,0,MAX(J9,K9)) | M9: =Inventory_Master!K9 | N9: =Inventory_Master!L9 | O9: =L9*N9 | P9: =IF(L9>0,1,0) | Q9: =C9*Inventory_Master!D9*Cost_Assumptions!$B$4
A10: =Inventory_Master!A10 | B10: =Inventory_Master!B10 | C10: =Inventory_Master!E10 | D10: =Inventory_Master!F10 | E10: =Inventory_Master!G10 | F10: =Inventory_Master!H10 | G10: =Inventory_Master!I10 | H10: =IF(C10<=G10,"REORDER","OK") | I10: =D10*E10+F10+D10*Cost_Assumptions!$B$9 | J10: =MAX(0,I10-C10) | K10: =Inventory_Master!N10 | L10: =IF(J10=0,0,MAX(J10,K10)) | M10: =Inventory_Master!K10 | N10: =Inventory_Master!L10 | O10: =L10*N10 | P10: =IF(L10>0,1,0) | Q10: =C10*Inventory_Master!D10*Cost_Assumptions!$B$4
A11: =Inventory_Master!A11 | B11: =Inventory_Master!B11 | C11: =Inventory_Master!E11 | D11: =Inventory_Master!F11 | E11: =Inventory_Master!G11 | F11: =Inventory_Master!H11 | G11: =Inventory_Master!I11 | H11: =IF(C11<=G11,"REORDER","OK") | I11: =D11*E11+F11+D11*Cost_Assumptions!$B$9 | J11: =MAX(0,I11-C11) | K11: =Inventory_Master!N11 | L11: =IF(J11=0,0,MAX(J11,K11)) | M11: =Inventory_Master!K11 | N11: =Inventory_Master!L11 | O11: =L11*N11 | P11: =IF(L11>0,1,0) | Q11: =C11*Inventory_Master!D11*Cost_Assumptions!$B$4
A12: =Inventory_Master!A12 | B12: =Inventory_Master!B12 | C12: =Inventory_Master!E12 | D12: =Inventory_Master!F12 | E12: =Inventory_Master!G12 | F12: =Inventory_Master!H12 | G12: =Inventory_Master!I12 | H12: =IF(C12<=G12,"REORDER","OK") | I12: =D12*E12+F12+D12*Cost_Assumptions!$B$9 | J12: =MAX(0,I12-C12) | K12: =Inventory_Master!N12 | L12: =IF(J12=0,0,MAX(J12,K12)) | M12: =Inventory_Master!K12 | N12: =Inventory_Master!L12 | O12: =L12*N12 | P12: =IF(L12>0,1,0) | Q12: =C12*Inventory_Master!D12*Cost_Assumptions!$B$4
A13: =Inventory_Master!A13 | B13: =Inventory_Master!B13 | C13: =Inventory_Master!E13 | D13: =Inventory_Master!F13 | E13: =Inventory_Master!G13 | F13: =Inventory_Master!H13 | G13: =Inventory_Master!I13 | H13: =IF(C13<=G13,"REORDER","OK") | I13: =D13*E13+F13+D13*Cost_Assumptions!$B$9 | J13: =MAX(0,I13-C13) | K13: =Inventory_Master!N13 | L13: =IF(J13=0,0,MAX(J13,K13)) | M13: =Inventory_Master!K13 | N13: =Inventory_Master!L13 | O13: =L13*N13 | P13: =IF(L13>0,1,0) | Q13: =C13*Inventory_Master!D13*Cost_Assumptions!$B$4
A14: =Inventory_Master!A14 | B14: =Inventory_Master!B14 | C14: =Inventory_Master!E14 | D14: =Inventory_Master!F14 | E14: =Inventory_Master!G14 | F14: =Inventory_Master!H14 | G14: =Inventory_Master!I14 | H14: =IF(C14<=G14,"REORDER","OK") | I14: =D14*E14+F14+D14*Cost_Assumptions!$B$9 | J14: =MAX(0,I14-C14) | K14: =Inventory_Master!N14 | L14: =IF(J14=0,0,MAX(J14,K14)) | M14: =Inventory_Master!K14 | N14: =Inventory_Master!L14 | O14: =L14*N14 | P14: =IF(L14>0,1,0) | Q14: =C14*Inventory_Master!D14*Cost_Assumptions!$B$4
A15: =Inventory_Master!A15 | B15: =Inventory_Master!B15 | C15: =Inventory_Master!E15 | D15: =Inventory_Master!F15 | E15: =Inventory_Master!G15 | F15: =Inventory_Master!H15 | G15: =Inventory_Master!I15 | H15: =IF(C15<=G15,"REORDER","OK") | I15: =D15*E15+F15+D15*Cost_Assumptions!$B$9 | J15: =MAX(0,I15-C15) | K15: =Inventory_Master!N15 | L15: =IF(J15=0,0,MAX(J15,K15)) | M15: =Inventory_Master!K15 | N15: =Inventory_Master!L15 | O15: =L15*N15 | P15: =IF(L15>0,1,0) | Q15: =C15*Inventory_Master!D15*Cost_Assumptions!$B$4
... A33: =Inventory_Master!A33 | B33: =Inventory_Master!B33 | C33: =Inventory_Master!E33 | D33: =Inventory_Master!F33 | E33: =Inventory_Master!G33 | F33: =Inventory_Master!H33 | G33: =Inventory_Master!I33 | H33: =IF(C33<=G33,"REORDER","OK") | I33: =D33*E33+F33+D33*Cost_Assumptions!$B$9 | J33: =MAX(0,I33-C33) | K33: =Inventory_Master!N33 | L33: =IF(J33=0,0,MAX(J33,K33)) | M33: =Inventory_Master!K33 | N33: =Inventory_Master!L33 | O33: =L33*N33 | P33: =IF(L33>0,1,0) | Q33: =C33*Inventory_Master!D33*Cost_Assumptions!$B$4

Sheet Scenario_Analysis
A1: Scenario Analysis
A2: Three scenarios per SKU. Suggested order quantity includes target stock cover and supplier MOQ.
A3: SKU | B3: Product | C3: Scenario | D3: Daily Demand | E3: Lead Time (days) | F3: Safety Stock | G3: Scenario Reorder Point | H3: Current Stock | I3: Gap to Reorder Point | J3: Target Stock | K3: Suggested Order Qty (MOQ-adjusted) | L3: Estimated Purchase Cost (₹)
A4: =Inventory_Master!A4 | B4: =Inventory_Master!B4 | C4: Baseline | D4: =Inventory_Master!F4 | E4: =Inventory_Master!G4 | F4: =Inventory_Master!H4 | G4: =D4*E4+F4 | H4: =Inventory_Master!E4 | I4: =MAX(0,G4-H4) | J4: =D4*E4+F4+D4*Cost_Assumptions!$B$9 | K4: =IF(J4<=H4,0,MAX(J4-H4,Inventory_Master!N4)) | L4: =K4*Inventory_Master!L4
A5: =Inventory_Master!A4 | B5: =Inventory_Master!B4 | C5: High Demand | D5: =Inventory_Master!F4*Cost_Assumptions!$B$7 | E5: =Inventory_Master!G4 | F5: =Inventory_Master!H4 | G5: =D5*E5+F5 | H5: =Inventory_Master!E4 | I5: =MAX(0,G5-H5) | J5: =D5*E5+F5+D5*Cost_Assumptions!$B$9 | K5: =IF(J5<=H5,0,MAX(J5-H5,Inventory_Master!N4)) | L5: =K5*Inventory_Master!L4
A6: =Inventory_Master!A4 | B6: =Inventory_Master!B4 | C6: Supplier Delay | D6: =Inventory_Master!F4 | E6: =Inventory_Master!G4+Cost_Assumptions!$B$8 | F6: =Inventory_Master!H4 | G6: =D6*E6+F6 | H6: =Inventory_Master!E4 | I6: =MAX(0,G6-H6) | J6: =D6*E6+F6+D6*Cost_Assumptions!$B$9 | K6: =IF(J6<=H6,0,MAX(J6-H6,Inventory_Master!N4)) | L6: =K6*Inventory_Master!L4
A7: =Inventory_Master!A5 | B7: =Inventory_Master!B5 | C7: Baseline | D7: =Inventory_Master!F5 | E7: =Inventory_Master!G5 | F7: =Inventory_Master!H5 | G7: =D7*E7+F7 | H7: =Inventory_Master!E5 | I7: =MAX(0,G7-H7) | J7: =D7*E7+F7+D7*Cost_Assumptions!$B$9 | K7: =IF(J7<=H7,0,MAX(J7-H7,Inventory_Master!N5)) | L7: =K7*Inventory_Master!L5
A8: =Inventory_Master!A5 | B8: =Inventory_Master!B5 | C8: High Demand | D8: =Inventory_Master!F5*Cost_Assumptions!$B$7 | E8: =Inventory_Master!G5 | F8: =Inventory_Master!H5 | G8: =D8*E8+F8 | H8: =Inventory_Master!E5 | I8: =MAX(0,G8-H8) | J8: =D8*E8+F8+D8*Cost_Assumptions!$B$9 | K8: =IF(J8<=H8,0,MAX(J8-H8,Inventory_Master!N5)) | L8: =K8*Inventory_Master!L5
A9: =Inventory_Master!A5 | B9: =Inventory_Master!B5 | C9: Supplier Delay | D9: =Inventory_Master!F5 | E9: =Inventory_Master!G5+Cost_Assumptions!$B$8 | F9: =Inventory_Master!H5 | G9: =D9*E9+F9 | H9: =Inventory_Master!E5 | I9: =MAX(0,G9-H9) | J9: =D9*E9+F9+D9*Cost_Assumptions!$B$9 | K9: =IF(J9<=H9,0,MAX(J9-H9,Inventory_Master!N5)) | L9: =K9*Inventory_Master!L5
A10: =Inventory_Master!A6 | B10: =Inventory_Master!B6 | C10: Baseline | D10: =Inventory_Master!F6 | E10: =Inventory_Master!G6 | F10: =Inventory_Master!H6 | G10: =D10*E10+F10 | H10: =Inventory_Master!E6 | I10: =MAX(0,G10-H10) | J10: =D10*E10+F10+D10*Cost_Assumptions!$B$9 | K10: =IF(J10<=H10,0,MAX(J10-H10,Inventory_Master!N6)) | L10: =K10*Inventory_Master!L6
A11: =Inventory_Master!A6 | B11: =Inventory_Master!B6 | C11: High Demand | D11: =Inventory_Master!F6*Cost_Assumptions!$B$7 | E11: =Inventory_Master!G6 | F11: =Inventory_Master!H6 | G11: =D11*E11+F11 | H11: =Inventory_Master!E6 | I11: =MAX(0,G11-H11) | J11: =D11*E11+F11+D11*Cost_Assumptions!$B$9 | K11: =IF(J11<=H11,0,MAX(J11-H11,Inventory_Master!N6)) | L11: =K11*Inventory_Master!L6
A12: =Inventory_Master!A6 | B12: =Inventory_Master!B6 | C12: Supplier Delay | D12: =Inventory_Master!F6 | E12: =Inventory_Master!G6+Cost_Assumptions!$B$8 | F12: =Inventory_Master!H6 | G12: =D12*E12+F12 | H12: =Inventory_Master!E6 | I12: =MAX(0,G12-H12) | J12: =D12*E12+F12+D12*Cost_Assumptions!$B$9 | K12: =IF(J12<=H12,0,MAX(J12-H12,Inventory_Master!N6)) | L12: =K12*Inventory_Master!L6
A13: =Inventory_Master!A7 | B13: =Inventory_Master!B7 | C13: Baseline | D13: =Inventory_Master!F7 | E13: =Inventory_Master!G7 | F13: =Inventory_Master!H7 | G13: =D13*E13+F13 | H13: =Inventory_Master!E7 | I13: =MAX(0,G13-H13) | J13: =D13*E13+F13+D13*Cost_Assumptions!$B$9 | K13: =IF(J13<=H13,0,MAX(J13-H13,Inventory_Master!N7)) | L13: =K13*Inventory_Master!L7
A14: =Inventory_Master!A7 | B14: =Inventory_Master!B7 | C14: High Demand | D14: =Inventory_Master!F7*Cost_Assumptions!$B$7 | E14: =Inventory_Master!G7 | F14: =Inventory_Master!H7 | G14: =D14*E14+F14 | H14: =Inventory_Master!E7 | I14: =MAX(0,G14-H14) | J14: =D14*E14+F14+D14*Cost_Assumptions!$B$9 | K14: =IF(J14<=H14,0,MAX(J14-H14,Inventory_Master!N7)) | L14: =K14*Inventory_Master!L7
A15: =Inventory_Master!A7 | B15: =Inventory_Master!B7 | C15: Supplier Delay | D15: =Inventory_Master!F7 | E15: =Inventory_Master!G7+Cost_Assumptions!$B$8 | F15: =Inventory_Master!H7 | G15: =D15*E15+F15 | H15: =Inventory_Master!E7 | I15: =MAX(0,G15-H15) | J15: =D15*E15+F15+D15*Cost_Assumptions!$B$9 | K15: =IF(J15<=H15,0,MAX(J15-H15,Inventory_Master!N7)) | L15: =K15*Inventory_Master!L7
A16: =Inventory_Master!A8 | B16: =Inventory_Master!B8 | C16: Baseline | D16: =Inventory_Master!F8 | E16: =Inventory_Master!G8 | F16: =Inventory_Master!H8 | G16: =D16*E16+F16 | H16: =Inventory_Master!E8 | I16: =MAX(0,G16-H16) | J16: =D16*E16+F16+D16*Cost_Assumptions!$B$9 | K16: =IF(J16<=H16,0,MAX(J16-H16,Inventory_Master!N8)) | L16: =K16*Inventory_Master!L8
A17: =Inventory_Master!A8 | B17: =Inventory_Master!B8 | C17: High Demand | D17: =Inventory_Master!F8*Cost_Assumptions!$B$7 | E17: =Inventory_Master!G8 | F17: =Inventory_Master!H8 | G17: =D17*E17+F17 | H17: =Inventory_Master!E8 | I17: =MAX(0,G17-H17) | J17: =D17*E17+F17+D17*Cost_Assumptions!$B$9 | K17: =IF(J17<=H17,0,MAX(J17-H17,Inventory_Master!N8)) | L17: =K17*Inventory_Master!L8
A18: =Inventory_Master!A8 | B18: =Inventory_Master!B8 | C18: Supplier Delay | D18: =Inventory_Master!F8 | E18: =Inventory_Master!G8+Cost_Assumptions!$B$8 | F18: =Inventory_Master!H8 | G18: =D18*E18+F18 | H18: =Inventory_Master!E8 | I18: =MAX(0,G18-H18) | J18: =D18*E18+F18+D18*Cost_Assumptions!$B$9 | K18: =IF(J18<=H18,0,MAX(J18-H18,Inventory_Master!N8)) | L18: =K18*Inventory_Master!L8
A19: =Inventory_Master!A9 | B19: =Inventory_Master!B9 | C19: Baseline | D19: =Inventory_Master!F9 | E19: =Inventory_Master!G9 | F19: =Inventory_Master!H9 | G19: =D19*E19+F19 | H19: =Inventory_Master!E9 | I19: =MAX(0,G19-H19) | J19: =D19*E19+F19+D19*Cost_Assumptions!$B$9 | K19: =IF(J19<=H19,0,MAX(J19-H19,Inventory_Master!N9)) | L19: =K19*Inventory_Master!L9
A20: =Inventory_Master!A9 | B20: =Inventory_Master!B9 | C20: High Demand | D20: =Inventory_Master!F9*Cost_Assumptions!$B$7 | E20: =Inventory_Master!G9 | F20: =Inventory_Master!H9 | G20: =D20*E20+F20 | H20: =Inventory_Master!E9 | I20: =MAX(0,G20-H20) | J20: =D20*E20+F20+D20*Cost_Assumptions!$B$9 | K20: =IF(J20<=H20,0,MAX(J20-H20,Inventory_Master!N9)) | L20: =K20*Inventory_Master!L9
A21: =Inventory_Master!A9 | B21: =Inventory_Master!B9 | C21: Supplier Delay | D21: =Inventory_Master!F9 | E21: =Inventory_Master!G9+Cost_Assumptions!$B$8 | F21: =Inventory_Master!H9 | G21: =D21*E21+F21 | H21: =Inventory_Master!E9 | I21: =MAX(0,G21-H21) | J21: =D21*E21+F21+D21*Cost_Assumptions!$B$9 | K21: =IF(J21<=H21,0,MAX(J21-H21,Inventory_Master!N9)) | L21: =K21*Inventory_Master!L9
A22: =Inventory_Master!A10 | B22: =Inventory_Master!B10 | C22: Baseline | D22: =Inventory_Master!F10 | E22: =Inventory_Master!G10 | F22: =Inventory_Master!H10 | G22: =D22*E22+F22 | H22: =Inventory_Master!E10 | I22: =MAX(0,G22-H22) | J22: =D22*E22+F22+D22*Cost_Assumptions!$B$9 | K22: =IF(J22<=H22,0,MAX(J22-H22,Inventory_Master!N10)) | L22: =K22*Inventory_Master!L10
A23: =Inventory_Master!A10 | B23: =Inventory_Master!B10 | C23: High Demand | D23: =Inventory_Master!F10*Cost_Assumptions!$B$7 | E23: =Inventory_Master!G10 | F23: =Inventory_Master!H10 | G23: =D23*E23+F23 | H23: =Inventory_Master!E10 | I23: =MAX(0,G23-H23) | J23: =D23*E23+F23+D23*Cost_Assumptions!$B$9 | K23: =IF(J23<=H23,0,MAX(J23-H23,Inventory_Master!N10)) | L23: =K23*Inventory_Master!L10
A24: =Inventory_Master!A10 | B24: =Inventory_Master!B10 | C24: Supplier Delay | D24: =Inventory_Master!F10 | E24: =Inventory_Master!G10+Cost_Assumptions!$B$8 | F24: =Inventory_Master!H10 | G24: =D24*E24+F24 | H24: =Inventory_Master!E10 | I24: =MAX(0,G24-H24) | J24: =D24*E24+F24+D24*Cost_Assumptions!$B$9 | K24: =IF(J24<=H24,0,MAX(J24-H24,Inventory_Master!N10)) | L24: =K24*Inventory_Master!L10
A25: =Inventory_Master!A11 | B25: =Inventory_Master!B11 | C25: Baseline | D25: =Inventory_Master!F11 | E25: =Inventory_Master!G11 | F25: =Inventory_Master!H11 | G25: =D25*E25+F25 | H25: =Inventory_Master!E11 | I25: =MAX(0,G25-H25) | J25: =D25*E25+F25+D25*Cost_Assumptions!$B$9 | K25: =IF(J25<=H25,0,MAX(J25-H25,Inventory_Master!N11)) | L25: =K25*Inventory_Master!L11
A26: =Inventory_Master!A11 | B26: =Inventory_Master!B11 | C26: High Demand | D26: =Inventory_Master!F11*Cost_Assumptions!$B$7 | E26: =Inventory_Master!G11 | F26: =Inventory_Master!H11 | G26: =D26*E26+F26 | H26: =Inventory_Master!E11 | I26: =MAX(0,G26-H26) | J26: =D26*E26+F26+D26*Cost_Assumptions!$B$9 | K26: =IF(J26<=H26,0,MAX(J26-H26,Inventory_Master!N11)) | L26: =K26*Inventory_Master!L11
A27: =Inventory_Master!A11 | B27: =Inventory_Master!B11 | C27: Supplier Delay | D27: =Inventory_Master!F11 | E27: =Inventory_Master!G11+Cost_Assumptions!$B$8 | F27: =Inventory_Master!H11 | G27: =D27*E27+F27 | H27: =Inventory_Master!E11 | I27: =MAX(0,G27-H27) | J27: =D27*E27+F27+D27*Cost_Assumptions!$B$9 | K27: =IF(J27<=H27,0,MAX(J27-H27,Inventory_Master!N11)) | L27: =K27*Inventory_Master!L11
A28: =Inventory_Master!A12 | B28: =Inventory_Master!B12 | C28: Baseline | D28: =Inventory_Master!F12 | E28: =Inventory_Master!G12 | F28: =Inventory_Master!H12 | G28: =D28*E28+F28 | H28: =Inventory_Master!E12 | I28: =MAX(0,G28-H28) | J28: =D28*E28+F28+D28*Cost_Assumptions!$B$9 | K28: =IF(J28<=H28,0,MAX(J28-H28,Inventory_Master!N12)) | L28: =K28*Inventory_Master!L12
A29: =Inventory_Master!A12 | B29: =Inventory_Master!B12 | C29: High Demand | D29: =Inventory_Master!F12*Cost_Assumptions!$B$7 | E29: =Inventory_Master!G12 | F29: =Inventory_Master!H12 | G29: =D29*E29+F29 | H29: =Inventory_Master!E12 | I29: =MAX(0,G29-H29) | J29: =D29*E29+F29+D29*Cost_Assumptions!$B$9 | K29: =IF(J29<=H29,0,MAX(J29-H29,Inventory_Master!N12)) | L29: =K29*Inventory_Master!L12
A30: =Inventory_Master!A12 | B30: =Inventory_Master!B12 | C30: Supplier Delay | D30: =Inventory_Master!F12 | E30: =Inventory_Master!G12+Cost_Assumptions!$B$8 | F30: =Inventory_Master!H12 | G30: =D30*E30+F30 | H30: =Inventory_Master!E12 | I30: =MAX(0,G30-H30) | J30: =D30*E30+F30+D30*Cost_Assumptions!$B$9 | K30: =IF(J30<=H30,0,MAX(J30-H30,Inventory_Master!N12)) | L30: =K30*Inventory_Master!L12
A31: =Inventory_Master!A13 | B31: =Inventory_Master!B13 | C31: Baseline | D31: =Inventory_Master!F13 | E31: =Inventory_Master!G13 | F31: =Inventory_Master!H13 | G31: =D31*E31+F31 | H31: =Inventory_Master!E13 | I31: =MAX(0,G31-H31) | J31: =D31*E31+F31+D31*Cost_Assumptions!$B$9 | K31: =IF(J31<=H31,0,MAX(J31-H31,Inventory_Master!N13)) | L31: =K31*Inventory_Master!L13
A32: =Inventory_Master!A13 | B32: =Inventory_Master!B13 | C32: High Demand | D32: =Inventory_Master!F13*Cost_Assumptions!$B$7 | E32: =Inventory_Master!G13 | F32: =Inventory_Master!H13 | G32: =D32*E32+F32 | H32: =Inventory_Master!E13 | I32: =MAX(0,G32-H32) | J32: =D32*E32+F32+D32*Cost_Assumptions!$B$9 | K32: =IF(J32<=H32,0,MAX(J32-H32,Inventory_Master!N13)) | L32: =K32*Inventory_Master!L13
A33: =Inventory_Master!A13 | B33: =Inventory_Master!B13 | C33: Supplier Delay | D33: =Inventory_Master!F13 | E33: =Inventory_Master!G13+Cost_Assumptions!$B$8 | F33: =Inventory_Master!H13 | G33: =D33*E33+F33 | H33: =Inventory_Master!E13 | I33: =MAX(0,G33-H33) | J33: =D33*E33+F33+D33*Cost_Assumptions!$B$9 | K33: =IF(J33<=H33,0,MAX(J33-H33,Inventory_Master!N13)) | L33: =K33*Inventory_Master!L13
A34: =Inventory_Master!A14 | B34: =Inventory_Master!B14 | C34: Baseline | D34: =Inventory_Master!F14 | E34: =Inventory_Master!G14 | F34: =Inventory_Master!H14 | G34: =D34*E34+F34 | H34: =Inventory_Master!E14 | I34: =MAX(0,G34-H34) | J34: =D34*E34+F34+D34*Cost_Assumptions!$B$9 | K34: =IF(J34<=H34,0,MAX(J34-H34,Inventory_Master!N14)) | L34: =K34*Inventory_Master!L14
A35: =Inventory_Master!A14 | B35: =Inventory_Master!B14 | C35: High Demand | D35: =Inventory_Master!F14*Cost_Assumptions!$B$7 | E35: =Inventory_Master!G14 | F35: =Inventory_Master!H14 | G35: =D35*E35+F35 | H35: =Inventory_Master!E14 | I35: =MAX(0,G35-H35) | J35: =D35*E35+F35+D35*Cost_Assumptions!$B$9 | K35: =IF(J35<=H35,0,MAX(J35-H35,Inventory_Master!N14)) | L35: =K35*Inventory_Master!L14
A36: =Inventory_Master!A14 | B36: =Inventory_Master!B14 | C36: Supplier Delay | D36: =Inventory_Master!F14 | E36: =Inventory_Master!G14+Cost_Assumptions!$B$8 | F36: =Inventory_Master!H14 | G36: =D36*E36+F36 | H36: =Inventory_Master!E14 | I36: =MAX(0,G36-H36) | J36: =D36*E36+F36+D36*Cost_Assumptions!$B$9 | K36: =IF(J36<=H36,0,MAX(J36-H36,Inventory_Master!N14)) | L36: =K36*Inventory_Master!L14
A37: =Inventory_Master!A15 | B37: =Inventory_Master!B15 | C37: Baseline | D37: =Inventory_Master!F15 | E37: =Inventory_Master!G15 | F37: =Inventory_Master!H15 | G37: =D37*E37+F37 | H37: =Inventory_Master!E15 | I37: =MAX(0,G37-H37) | J37: =D37*E37+F37+D37*Cost_Assumptions!$B$9 | K37: =IF(J37<=H37,0,MAX(J37-H37,Inventory_Master!N15)) | L37: =K37*Inventory_Master!L15
A38: =Inventory_Master!A15 | B38: =Inventory_Master!B15 | C38: High Demand | D38: =Inventory_Master!F15*Cost_Assumptions!$B$7 | E38: =Inventory_Master!G15 | F38: =Inventory_Master!H15 | G38: =D38*E38+F38 | H38: =Inventory_Master!E15 | I38: =MAX(0,G38-H38) | J38: =D38*E38+F38+D38*Cost_Assumptions!$B$9 | K38: =IF(J38<=H38,0,MAX(J38-H38,Inventory_Master!N15)) | L38: =K38*Inventory_Master!L15
A39: =Inventory_Master!A15 | B39: =Inventory_Master!B15 | C39: Supplier Delay | D39: =Inventory_Master!F15 | E39: =Inventory_Master!G15+Cost_Assumptions!$B$8 | F39: =Inventory_Master!H15 | G39: =D39*E39+F39 | H39: =Inventory_Master!E15 | I39: =MAX(0,G39-H39) | J39: =D39*E39+F39+D39*Cost_Assumptions!$B$9 | K39: =IF(J39<=H39,0,MAX(J39-H39,Inventory_Master!N15)) | L39: =K39*Inventory_Master!L15
A40: =Inventory_Master!A16 | B40: =Inventory_Master!B16 | C40: Baseline | D40: =Inventory_Master!F16 | E40: =Inventory_Master!G16 | F40: =Inventory_Master!H16 | G40: =D40*E40+F40 | H40: =Inventory_Master!E16 | I40: =MAX(0,G40-H40) | J40: =D40*E40+F40+D40*Cost_Assumptions!$B$9 | K40: =IF(J40<=H40,0,MAX(J40-H40,Inventory_Master!N16)) | L40: =K40*Inventory_Master!L16
...

Sheet Cost_Analysis
A1: Cost Analysis
A2: Estimated annual holding costs and modeled procurement costs; interpret as scenario estimates, not accounting actuals.
A3: SKU | B3: Product | C3: Current Inventory Value (₹) | D3: Suggested Order Qty | E3: Suggested Purchase Cost (₹) | F3: Annual Holding Cost (₹) | G3: Estimated Order Processing Cost (₹) | H3: Illustrative Stockout Risk Units | I3: Illustrative Stockout Risk Cost (₹)
A4: =Inventory_Master!A4 | B4: =Inventory_Master!B4 | C4: =Inventory_Master!J4 | D4: =Replenishment_Plan!L4 | E4: =Replenishment_Plan!O4 | F4: =C4*Cost_Assumptions!$B$4 | G4: =IF(D4>0,Cost_Assumptions!$B$5,0) | H4: =Replenishment_Plan!G4-Replenishment_Plan!C4 | I4: =MAX(0,H4)*Cost_Assumptions!$B$6
A5: =Inventory_Master!A5 | B5: =Inventory_Master!B5 | C5: =Inventory_Master!J5 | D5: =Replenishment_Plan!L5 | E5: =Replenishment_Plan!O5 | F5: =C5*Cost_Assumptions!$B$4 | G5: =IF(D5>0,Cost_Assumptions!$B$5,0) | H5: =Replenishment_Plan!G5-Replenishment_Plan!C5 | I5: =MAX(0,H5)*Cost_Assumptions!$B$6
A6: =Inventory_Master!A6 | B6: =Inventory_Master!B6 | C6: =Inventory_Master!J6 | D6: =Replenishment_Plan!L6 | E6: =Replenishment_Plan!O6 | F6: =C6*Cost_Assumptions!$B$4 | G6: =IF(D6>0,Cost_Assumptions!$B$5,0) | H6: =Replenishment_Plan!G6-Replenishment_Plan!C6 | I6: =MAX(0,H6)*Cost_Assumptions!$B$6
A7: =Inventory_Master!A7 | B7: =Inventory_Master!B7 | C7: =Inventory_Master!J7 | D7: =Replenishment_Plan!L7 | E7: =Replenishment_Plan!O7 | F7: =C7*Cost_Assumptions!$B$4 | G7: =IF(D7>0,Cost_Assumptions!$B$5,0) | H7: =Replenishment_Plan!G7-Replenishment_Plan!C7 | I7: =MAX(0,H7)*Cost_Assumptions!$B$6
A8: =Inventory_Master!A8 | B8: =Inventory_Master!B8 | C8: =Inventory_Master!J8 | D8: =Replenishment_Plan!L8 | E8: =Replenishment_Plan!O8 | F8: =C8*Cost_Assumptions!$B$4 | G8: =IF(D8>0,Cost_Assumptions!$B$5,0) | H8: =Replenishment_Plan!G8-Replenishment_Plan!C8 | I8: =MAX(0,H8)*Cost_Assumptions!$B$6
A9: =Inventory_Master!A9 | B9: =Inventory_Master!B9 | C9: =Inventory_Master!J9 | D9: =Replenishment_Plan!L9 | E9: =Replenishment_Plan!O9 | F9: =C9*Cost_Assumptions!$B$4 | G9: =IF(D9>0,Cost_Assumptions!$B$5,0) | H9: =Replenishment_Plan!G9-Replenishment_Plan!C9 | I9: =MAX(0,H9)*Cost_Assumptions!$B$6
A10: =Inventory_Master!A10 | B10: =Inventory_Master!B10 | C10: =Inventory_Master!J10 | D10: =Replenishment_Plan!L10 | E10: =Replenishment_Plan!O10 | F10: =C10*Cost_Assumptions!$B$4 | G10: =IF(D10>0,Cost_Assumptions!$B$5,0) | H10: =Replenishment_Plan!G10-Replenishment_Plan!C10 | I10: =MAX(0,H10)*Cost_Assumptions!$B$6
A11: =Inventory_Master!A11 | B11: =Inventory_Master!B11 | C11: =Inventory_Master!J11 | D11: =Replenishment_Plan!L11 | E11: =Replenishment_Plan!O11 | F11: =C11*Cost_Assumptions!$B$4 | G11: =IF(D11>0,Cost_Assumptions!$B$5,0) | H11: =Replenishment_Plan!G11-Replenishment_Plan!C11 | I11: =MAX(0,H11)*Cost_Assumptions!$B$6
A12: =Inventory_Master!A12 | B12: =Inventory_Master!B12 | C12: =Inventory_Master!J12 | D12: =Replenishment_Plan!L12 | E12: =Replenishment_Plan!O12 | F12: =C12*Cost_Assumptions!$B$4 | G12: =IF(D12>0,Cost_Assumptions!$B$5,0) | H12: =Replenishment_Plan!G12-Replenishment_Plan!C12 | I12: =MAX(0,H12)*Cost_Assumptions!$B$6
A13: =Inventory_Master!A13 | B13: =Inventory_Master!B13 | C13: =Inventory_Master!J13 | D13: =Replenishment_Plan!L13 | E13: =Replenishment_Plan!O13 | F13: =C13*Cost_Assumptions!$B$4 | G13: =IF(D13>0,Cost_Assumptions!$B$5,0) | H13: =Replenishment_Plan!G13-Replenishment_Plan!C13 | I13: =MAX(0,H13)*Cost_Assumptions!$B$6
A14: =Inventory_Master!A14 | B14: =Inventory_Master!B14 | C14: =Inventory_Master!J14 | D14: =Replenishment_Plan!L14 | E14: =Replenishment_Plan!O14 | F14: =C14*Cost_Assumptions!$B$4 | G14: =IF(D14>0,Cost_Assumptions!$B$5,0) | H14: =Replenishment_Plan!G14-Replenishment_Plan!C14 | I14: =MAX(0,H14)*Cost_Assumptions!$B$6
A15: =Inventory_Master!A15 | B15: =Inventory_Master!B15 | C15: =Inventory_Master!J15 | D15: =Replenishment_Plan!L15 | E15: =Replenishment_Plan!O15 | F15: =C15*Cost_Assumptions!$B$4 | G15: =IF(D15>0,Cost_Assumptions!$B$5,0) | H15: =Replenishment_Plan!G15-Replenishment_Plan!C15 | I15: =MAX(0,H15)*Cost_Assumptions!$B$6
... A33: =Inventory_Master!A33 | B33: =Inventory_Master!B33 | C33: =Inventory_Master!J33 | D33: =Replenishment_Plan!L33 | E33: =Replenishment_Plan!O33 | F33: =C33*Cost_Assumptions!$B$4 | G33: =IF(D33>0,Cost_Assumptions!$B$5,0) | H33: =Replenishment_Plan!G33-Replenishment_Plan!C33 | I33: =MAX(0,H33)*Cost_Assumptions!$B$6

Sheet Management_Dashboard
A1: Inventory & Procurement Dashboard
A2: Synthetic data | Review Excel-calculated values before writing final findings.
A4: KEY PERFORMANCE INDICATORS
A5: Total Inventory Value | B5: =SUM(Inventory_Master!J4:J33) | D5: Products to Reorder | E5: =COUNTIF(Replenishment_Plan!H4:H33,"REORDER") | G5: Suggested Purchase Cost | H5: =SUM(Replenishment_Plan!O4:O33)
A8: Total SKUs | B8: =COUNTA(Inventory_Master!A4:A33) | D8: Supplier Quotes | E8: =COUNTA(Supplier_Comparison!C4:C93) | G8: Annual Holding Cost | H8: =SUM(Cost_Analysis!F4:F33)
A11: Reorder Order Count | B11: =SUM(Replenishment_Plan!P4:P33) | D11: Estimated Order Processing Cost | E11: =SUM(Cost_Analysis!G4:G33) | G11: Illustrative Stockout Risk Cost | H11: =SUM(Cost_Analysis!I4:I33)
A15: Inventory Value by Category
A16: Category | B16: Inventory Value (₹)
A17: Electronics | B17: =SUMIF(Inventory_Master!$C$4:$C$33,A17,Inventory_Master!$J$4:$J$33)
A18: Home | B18: =SUMIF(Inventory_Master!$C$4:$C$33,A18,Inventory_Master!$J$4:$J$33)
A19: Lifestyle | B19: =SUMIF(Inventory_Master!$C$4:$C$33,A19,Inventory_Master!$J$4:$J$33)
A20: Stationery | B20: =SUMIF(Inventory_Master!$C$4:$C$33,A20,Inventory_Master!$J$4:$J$33)
A21: Fitness | B21: =SUMIF(Inventory_Master!$C$4:$C$33,A21,Inventory_Master!$J$4:$J$33)
A24: Replenishment Status
A25: Status | B25: Number of SKUs
A26: REORDER | B26: =COUNTIF(Replenishment_Plan!H4:H33,"REORDER")
A27: OK | B27: =COUNTIF(Replenishment_Plan!H4:H33,"OK")
A30: Questions for your written analysis
A31: 1. Which category has the highest inventory value?
A32: 2. Which SKUs are below the reorder point?
A33: 3. Do the highest-scoring suppliers also offer the lowest price?
A34: 4. How does high demand change suggested order quantities?
A35: 5. What are the trade-offs between low cost and fast delivery?
